Workbook

Sheet 1. Cover & Summary
B2: VoltRides Pvt Ltd
B3: E-Bike Manufacturing Plant — Optimized Layout & Operations Plan
B4: Target: 5,000 bikes/yr · Single shift · 250 days · 480 min/day · 24 min takt
B5: Version 1.0 · 19 May 2026 · Master planning workbook
B7: KEY METRICS
B8: Building footprint | C8: 150 ft × 80 ft | E8: Total headcount | F8: 50
B9: Total floor area | C9: 12000 | E9: Direct labour | F9: 32
B10: Functional area | C10: 4880 | E10: Indirect labour | F10: 18
B11: Aisles & clearances | C11: 7120 | E11: Bikes / day (takt 24 min) | F11: 20
B12: Functional utilisation | C12: =C10/C9 -> 0.40666667 | E12: Annual production target | F12: 5000
B14: FINANCIAL SUMMARY (PKR)
B15: CapEx — Quoted (AIT) | C15: ='8. CapEx Quoted'!G15 -> 11278000 | E15: Annual labour cost | F15: ='7. Labour Cost'!G60 -> 45540000
B16: CapEx — Additional est. | C16: ='9. CapEx Additional'!D20 -> 6575000 | E16: Monthly labour cost | F16: ='7. Labour Cost'!G59 -> 3795000
B17: Total Plant Equipment CapEx | C17: =C15+C16 -> 17853000 | E17: Annual labour / bike | F17: =F15/F12 -> 9108
B18: Civil / electrical / land | C18: TBD — see note | E18: Equipment CapEx / bike | F18: =C17/F12 -> 3570.6
B20: CONTENTS
B21: 1. Cover & Summary | C21: This sheet — top-level numbers and navigation
B22: 2. Plant Layout | C22: Visual block diagram, to scale (1 cell = 4 ft)
B23: 3. Space Schedule | C23: Zone-by-zone footprint with %
B24: 4. Sub-Assemblies | C24: SA-01 to SA-11 — stations, skills, feeds
B25: 5. Main Assembly Line | C25: MA-01 to MA-06 — operations and takt
B26: 6. Headcount | C26: Full 50-person breakdown by section
B27: 7. Labour Cost | C27: Salary × headcount = monthly & annual cost
B28: 8. CapEx Quoted | C28: From AIT quote F18-1109B-176 (PKR 11.28 M)
B29: 9. CapEx Additional | C29: Items NOT in quote — estimated
B30: 10. CapEx Summary | C30: Roll-up of all capital costs
B31: 11. Assumptions & Notes | C31: Key assumptions, open items, things to verify
B34: CELL COLOUR KEY
C35: Yellow background | D35: User-editable input (e.g. salary rates). Replace with your actuals.
C36: Light blue | D36: Subtotal / section summary row
C37: Indigo (white text) | D37: Grand total / header row

Sheet 2. Plant Layout
B2: VoltRides Plant Layout — 150 ft × 80 ft (12,000 sq ft)
B3: Scale: 1 cell ≈ 4 ft · Target: 5,000 bikes/yr · Material flow: Incoming → Weld → Frame Tag → Paint → Sub-Assy → Main Line → Test Bench → Finished Goods
Z4: 100ft
B5: OFFICES 4 × 12×12 ft 576 sq ft | I5: WELD SHOP 20×10 ft · 200 sq ft | AH5: INCOMING STORE 50×20 ft 1,000 sq ft
O6: SA-01 Frame | Q6: SA-02 Wheel | S6: SA-03 F.Fork | U6: SA-04 F.Elec | W6: SA-05 Hndlbr | Y6: SA-06 Cover
I8: FRAME TAG 10×10 ft 100 sq ft
O9: MAIN ASSEMBLY LINE → MA-01 · MA-02 · MA-03 · MA-04 · MA-05 · MA-06 (40 × 5 ft · 200 sq ft) | AB9: TEST BENCH 15×15 ft 225 sq ft (Standalone QC)
AM11: 50 ft
B12: PAINT SHOP 25×25 ft 625 sq ft | O12: SA-07 DiscBr | Q12: SA-08 WireH | S12: SA-09 SideCv | U12: SA-10 BattBox ★ | W12: SA-11 Tank
AB14: battery assem room
I19: FINISHED GOODS STORAGE Pack · stage · dispatch 50×25 ft · 1,250 sq ft
Y21: ← FORKLIFT AISLE →
B27: LEGEND & FOOTPRINTS
D28: Offices (4 × 12×12) | I28: 576 | K28: sq ft
D29: Weld Shop (20×10) | I29: 200 | K29: sq ft
D30: Frame Tagging (10×10) | I30: 100 | K30: sq ft
D31: Paint Shop (25×25) | I31: 625 | K31: sq ft
D32: Sub-Assemblies (11 × 8×8) | I32: 704 | K32: sq ft
D33: Main Line (40×5) | I33: 200 | K33: sq ft
D34: Test Bench (15×15) | I34: 225 | K34: sq ft
D35: Finished Goods (50×25) | I35: 1250 | K35: sq ft
D36: Incoming Goods (50×20) | I36: 1000 | K36: sq ft
B37: Functional total | I37: =SUM(I28:I36) -> 4880 | K37: sq ft
B38: Aisles, clearances, MH paths (= building − functional) | I38: =12000-I37 -> 7120 | K38: sq ft
B39: BUILDING TOTAL (150 × 80) | I39: 12000 | K39: sq ft
B41: ★ SA-10 (Battery Box) is a safety-critical / bottleneck station — always staffed by ≥ 2 skilled workers, never under-staff.

Sheet 3. Space Schedule
B2: Space Schedule — Zone Footprints
B3: All zones inside the 150 ft × 80 ft (12,000 sq ft) building
B5: Zone | C5: Length (ft) | D5: Width (ft) | E5: Area (sq ft) | F5: % of building | G5: Notes
B6: Offices (4 × 12×12) | C6: 24 | D6: 24 | E6: 576 | F6: =E6/$E$17 -> 0.048 | G6: 4 offices in 2×2 block, top-left, away from fumes & noise
B7: Weld Shop | C7: 20 | D7: 10 | E7: 200 | F7: =E7/$E$17 -> 0.016666667 | G7: Pre-processing — MIG/TIG, frame jigs
B8: Frame Tagging | C8: 10 | D8: 10 | E8: 100 | F8: =E8/$E$17 -> 0.0083333333 | G8: VIN / serial stamping + records
B9: Paint Shop | C9: 25 | D9: 25 | E9: 625 | F9: =E9/$E$17 -> 0.052083333 | G9: Booth + flash-off; ventilated zone
B10: Sub-Assemblies (11 × 8×8) | C10: — | D10: — | E10: 704 | F10: =E10/$E$17 -> 0.058666667 | G10: 6 top of main line + 5 bottom; 8×8 ft each; 4 ft clearance
B11: Main Assembly Line | C11: 40 | D11: 5 | E11: 200 | F11: =E11/$E$17 -> 0.016666667 | G11: MA-01 → MA-06; 40 ft long × 5 ft wide; takt 24 min
B12: Test Bench | C12: 15 | D12: 15 | E12: 225 | F12: =E12/$E$17 -> 0.01875 | G12: Standalone QC zone beyond MA-06
B13: Finished Goods | C13: 50 | D13: 25 | E13: 1250 | F13: =E13/$E$17 -> 0.10416667 | G13: Pack · stage · dispatch
B14: Incoming Goods | C14: 50 | D14: 20 | E14: 1000 | F14: =E14/$E$17 -> 0.083333333 | G14: Receiving from vendors; right wall
B15: FUNCTIONAL TOTAL | E15: =SUM(E6:E14) -> 4880 | F15: =E15/$E$17 -> 0.40666667
B16: Aisles, clearances, MH paths | E16: =E17-E15 -> 7120 | F16: =E16/$E$17 -> 0.59333333 | G16: Forklift lanes, fire egress, station-to-station walkways
B17: BUILDING TOTAL | C17: 150 | D17: 80 | E17: 12000 | F17: 1

Sheet 4. Sub-Assemblies
B2: Sub-Assembly Stations — SA-01 to SA-11
B3: Each station occupies 8 × 8 ft (64 sq ft). Total sub-assembly footprint: 704 sq ft.
B5: Station | C5: Description | D5: Feeds Into | E5: Skill Level | F5: Headcount | G5: Notes
B6: SA-01 | C6: Frame | D6: MA-01 | E6: Semi-skilled | F6: 1 | G6: Primary frame build
B7: SA-02 | C7: Wheel | D7: MA-01 | E7: Semi-skilled | F7: 1 | G7: Wheel assembly + spokes
B8: SA-03 | C8: Front Fork | D8: MA-02 | E8: Semi-skilled | F8: 1
B9: SA-04 | C9: Front Electrical | D9: MA-03 | E9: Skilled | F9: 1 | G9: Wiring complexity — skilled
B10: SA-05 | C10: Handlebar | D10: MA-03 | E10: Semi-skilled | F10: 1 | G10: Multi-skill with SA-06
B11: SA-06 | C11: Cover | D11: MA-04 | E11: Semi-skilled | F11: 1 | G11: Multi-skill with SA-05
B12: SA-07 | C12: Disc Brake | D12: MA-04 | E12: Semi-skilled | F12: 1 | G12: Multi-skill with SA-11
B13: SA-08 | C13: Wire Harness | D13: MA-04 | E13: Semi-skilled | F13: 1 | G13: Multi-skill with SA-11
B14: SA-09 | C14: Side Cover | D14: MA-05 | E14: Semi-skilled | F14: 1
B15: SA-10 | C15: Battery Box ★ | D15: MA-05 | E15: Skilled | F15: 2 | G15: ★ Safety-critical — always ≥ 2 workers, never under-staff
B16: SA-11 | C16: Tank | D16: MA-06 | E16: Semi-skilled | F16: 1 | G16: Multi-skill with SA-07/SA-08
B17: TOTAL | F17: =SUM(F6:F16) -> 12 | G17: 8 Semi-skilled + 3 Skilled (SA-04, SA-10 × 2)

Sheet 5. Main Assembly Line
B2: Main Assembly Line — MA-01 to MA-06
B3: Line: 40 ft × 5 ft (200 sq ft) · 6 stations · Takt 24 min/bike · 4 workers cover 6 stations via line balancing
B5: Station | C5: Operations | D5: Skill Level | E5: Receives From SA | F5: Worker Tag | G5: Notes
B6: MA-01 | C6: Frame placement + wheels | D6: Semi-skilled | E6: SA-01, SA-02 | F6: Worker A | G6: Walking worker shared with MA-02
B7: MA-02 | C7: Front fork mounting | D7: Semi-skilled | E7: SA-03 | F7: Worker A | G7: Same operator as MA-01
B8: MA-03 | C8: Handlebar + front electrical | D8: Semi-skilled | E8: SA-04, SA-05 | F8: Worker B | G8: Wiring routed in
B9: MA-04 | C9: Cover · disc brake · wire harness ★ | D9: Skilled | E9: SA-06, SA-07, SA-08 | F9: Worker C | G9: ★ Skilled — multiple sub-assys converge
B10: MA-05 | C10: Side cover + battery box | D10: Semi-skilled | E10: SA-09, SA-10 | F10: Worker B | G10: Same operator as MA-03
B11: MA-06 | C11: Tank + final OQC ★ | D11: Senior | E11: SA-11 | F11: Worker D | G11: ★ Senior — final quality sign-off
B13: MAIN LINE LABOUR SUMMARY
B14: Worker Tag | C14: Skill Level | D14: Stations Covered
B15: Worker A | C15: Semi-skilled | D15: MA-01 + MA-02 (walks between)
B16: Worker B | C16: Semi-skilled | D16: MA-03 + MA-05 (walks between)
B17: Worker C | C17: Skilled | D17: MA-04 dedicated (sub-assy convergence)
B18: Worker D | C18: Senior | D18: MA-06 dedicated (final OQC)
B19: MA TOTAL | C19: — | D19: 4 workers · 6 stations

Sheet 6. Headcount
B2: Plant Headcount — 5,000 bikes/yr
B3: Single shift · Lean coverage with role-sharing where safe
B5: Section | C5: Role / Station | D5: Skill Level | E5: Count | F5: Notes
B6: ASSEMBLY — 20 total
C7: Main Line operators (MA-01 → MA-06) | D7: Mixed | E7: 4 | F7: 2 Semi + 1 Skilled (MA-04) + 1 Senior (MA-06)
C8: Sub-Assembly operators (SA-01 → SA-11) | D8: Mixed | E8: 11 | F8: 8 Semi + 3 Skilled (SA-04, SA-10 × 2)
C9: Material Handler / Kitting | D9: Unskilled | E9: 1 | F9: Pre-kits parts; feeds stations
C10: Line Supervisor | D10: Senior | E10: 1 | F10: 1 per zone: Sub-Assy / Main Line / Pre-Proc / FG-Receiving | G10: can be reviewed
B11: PRE-PROCESSING (Weld · Frame Tag · Paint) — 7 total
C12: Welder | D12: Skilled | E12: 1 | F12: MIG / TIG; covers frame jigs
C13: Welder helper | D13: Unskilled | E13: 0 | F13: Tacking, fit-up, material
C14: Painter | D14: Skilled | E14: 1 | F14: Spray + oven cycle
C15: Paint helper | D15: Unskilled | E15: 1 | F15: Masking, hanging, transfer
C16: Frame Tagger | D16: Semi-skilled | E16: 0 | F16: VIN / serial stamping + records
B17: QUALITY · MAINTENANCE · STORES — 7 total
C18: QC Inspector (IQC + in-process) | D18: Skilled | E18: 1 | F18: MA-06 covers final OQC
C19: Mechanical Technician | D19: Skilled | E19: 0 | F19: Conveyor, jigs, fixtures
C20: Electrical Technician | D20: Skilled | E20: 0 | F20: Power, controls, paint oven
C21: Stores In-charge | D21: Semi-skilled | E21: 1 | F21: Receiving, issue, cycle count
C22: Stores Helper | D22: Unskilled | E22: 1 | F22: Unload, put-away, dispatch
B23: PROFESSIONALS — Management & Engineering — 9 total
C24: Plant Manager | D24: Professional | E24: 1 | F24: Overall P&L
C25: Production Manager | D25: Professional | E25: 0 | F25: Daily operations
C26: Quality Manager | D26: Professional | E26: 1 | F26: QMS, audits, supplier quality
C27: Industrial / Production Engineer | D27: Professional | E27: 0 | F27: Line balance, time studies
C28: Maintenance Engineer | D28: Professional | E28: 0 | F28: Preventive maint., spares
C29: Supply Chain Manager | D29: Professional | E29: 1 | F29: Vendors, planning, inventory
C30: HR & Admin Officer | D30: Professional | E30: 1 | F30: Lean role: HR + Admin combined
C31: Finance / Accounts | D31: Professional | E31: 1 | F31: Books, payroll, taxes
C32: Safety Officer (EHS) | D32: Professional | E32: 1 | F32: Mandatory; SA-10 + paint risk areas
B33: GENERAL SUPPORT — 7 total
C34: Security Guards | D34: Unskilled | E34: 2 | F34: Gate, patrols, night cover
C35: Housekeeping | D35: Unskilled | E35: 2 | F35: Production + offices
C36: Driver | D36: Unskilled | E36: 0 | F36: Company vehicle / errands
C37: Receptionist / Office Asst. | D37: Semi-skilled | E37: 1 | F37: Front desk, courier, docs
B38: PLANT TOTAL | E38: =SUM(E6:E37) -> 34 | F38: Single shift · 250 days · 480 min/day
B40: SKILL-MIX SUMMARY
B41: Skill Level | C41: Count | D41: % of Plant
B42: Unskilled | C42: 11 | D42: =C42/$E$38 -> 0.32352941
B43: Semi-skilled | C43: 13 | D43: =C43/$E$38 -> 0.38235294
...

Sheet 7. Labour Cost
B2: Labour Cost — Monthly & Annual
B3: ★ EDIT THE YELLOW CELLS — these are indicative Pakistani manufacturing rates (mid-2026). Replace with your company's actuals.
B5: PER-SKILL DEFAULT RATES (PKR / month) — editable
B6: Skill Level | C6: Default Monthly Salary (PKR)
B7: Unskilled | C7: 40000
B8: Semi-skilled | C8: 45000
B9: Skilled | C9: 65000
B10: Senior | C10: 90000
B12: PER-PROFESSIONAL ROLE RATES (PKR / month) — editable
B13: Role | C13: Default Monthly Salary (PKR)
B14: Plant Manager | C14: 250000
B15: Production Manager | C15: 250000
B16: Quality Manager | C16: 220000
B17: Industrial / Production Engineer | C17: 150000
B18: Maintenance Engineer | C18: 150000
B19: Supply Chain Manager | C19: 150000
B20: HR & Admin Officer | C20: 120000
B21: Finance / Accounts | C21: 150000
B22: Safety Officer (EHS) | C22: 100000
B25: HEADCOUNT × SALARY = MONTHLY & ANNUAL COST
B26: # | C26: Role / Station | D26: Skill | E26: Count | F26: Monthly Rate (PKR) | G26: Monthly Cost (PKR) | H26: Notes
B27: 1 | C27: Main Line · Worker A (MA-01/02) | D27: Semi-skilled | E27: 1 | F27: =C8 -> 45000 | G27: =E27*F27 -> 45000 | H27: Walking worker
B28: 2 | C28: Main Line · Worker B (MA-03/05) | D28: Semi-skilled | E28: 1 | F28: =C8 -> 45000 | G28: =E28*F28 -> 45000 | H28: Walking worker
B29: 3 | C29: Main Line · Worker C (MA-04 ★) | D29: Skilled | E29: 1 | F29: =C9 -> 65000 | G29: =E29*F29 -> 65000 | H29: ★ Sub-assy convergence
B30: 4 | C30: Main Line · Worker D (MA-06 ★) | D30: Senior | E30: 1 | F30: =C10 -> 90000 | G30: =E30*F30 -> 90000 | H30: ★ Final OQC
B31: 5 | C31: Sub-Assembly — Semi-skilled (×8) | D31: Semi-skilled | E31: 8 | F31: =C8 -> 45000 | G31: =E31*F31 -> 360000 | H31: SA-01,02,03,05,06,07,08,09,11
B32: 6 | C32: Sub-Assembly — Skilled (SA-04) | D32: Skilled | E32: 1 | F32: =C9 -> 65000 | G32: =E32*F32 -> 65000 | H32: Front electrical
B33: 7 | C33: Sub-Assembly — Skilled (SA-10 ★) | D33: Skilled | E33: 2 | F33: =C9 -> 65000 | G33: =E33*F33 -> 130000 | H33: ★ Battery box — never < 2
B34: 8 | C34: Material Handler / Kitting | D34: Unskilled | E34: 1 | F34: =C7 -> 40000 | G34: =E34*F34 -> 40000
B35: 9 | C35: Line Supervisor | D35: Senior | E35: 4 | F35: =C10 -> 90000 | G35: =E35*F35 -> 360000 | H35: 1 per zone (Sub-Assy / ML / Pre-Proc / FG)
B36: 10 | C36: Welder | D36: Skilled | E36: 2 | F36: =C9 -> 65000 | G36: =E36*F36 -> 130000
B37: 11 | C37: Welder helper | D37: Unskilled | E37: 1 | F37: =C7 -> 40000 | G37: =E37*F37 -> 40000
B38: 12 | C38: Painter | D38: Skilled | E38: 2 | F38: =C9 -> 65000 | G38: =E38*F38 -> 130000
B39: 13 | C39: Paint helper | D39: Unskilled | E39: 1 | F39: =C7 -> 40000 | G39: =E39*F39 -> 40000
B40: 14 | C40: Frame Tagger | D40: Semi-skilled | E40: 1 | F40: =C8 -> 45000 | G40: =E40*F40 -> 45000
B41: 15 | C41: QC Inspector | D41: Skilled | E41: 2 | F41: =C9 -> 65000 | G41: =E41*F41 -> 130000
B42: 16 | C42: Mechanical Technician | D42: Skilled | E42: 1 | F42: =C9 -> 65000 | G42: =E42*F42 -> 65000
B43: 17 | C43: Electrical Technician | D43: Skilled | E43: 1 | F43: =C9 -> 65000 | G43: =E43*F43 -> 65000
B44: 18 | C44: Stores In-charge | D44: Semi-skilled | E44: 1 | F44: =C8 -> 45000 | G44: =E44*F44 -> 45000
B45: 19 | C45: Stores Helper | D45: Unskilled | E45: 2 | F45: =C7 -> 40000 | G45: =E45*F45 -> 80000
...

Sheet 8. CapEx Quoted
B2: CapEx — Quoted (Automation Innovative Technologies)
B3: Quotation # F18-1109B-176 · Dated 5 May 2026 · Customer ID AIE148 · Contact: Ameer Ali (0300-5184846)
B4: Vendor: Automation Innovative Technologies · info.aiepk@gmail.com
B6: # | C6: Item | D6: Description (per quote) | E6: Unit Price (PKR) | F6: Qty | G6: Amount (PKR) | H6: Vendor Note
B7: 1 | C7: Assembly Line — Complete 60 ft | D7: Structure: Column & Beam, U-Channel. Column 3"×3" 18 gauge (base plate & 8 mm bolts). Beam 3"×3" 18 gauge. U-Channel 10" 18 gauge. Heavy-duty roller chain, duplex (2-strand), pitch 25.4 mm, bearing dia 15.88 mm. Breaking strength 6,500–7,500 kg. Working load 1,200–1,500 kg continuous. Motor gear capacity 3 HP. China bearings. Conveyor channel + covering sheet 18 gauge. VFD control panel. Powder-coat paint. | E7: 2650000 | F7: 1 | G7: =E7*F7 -> 2650000 | H7: All conveyor is extendable, easy to transfer
B8: 2 | C8: Paint Booth + Flash-off Gallery | D8: Paint Booth H 11′ × W 10′ × L 12′, 1 mm sheet. Flash-off H 11′ × W 10′ × L 8′, 1 mm sheet. Water curtain 8′ × 7′ galvanized 1.6 mm sheet. Floor plane 1½″ × 1½″ angle + 1″ square bar. Side pillar + base + junction pillar, 2 mm sheet. Vacuum blower 5 HP × 2. Fresh air blower 3 HP. | E8: 1945000 | F8: 1 | G8: =E8*F8 -> 1945000 | H8: Paint booth totally bolted and laser-CNC based
B9: 3 | C9: Phosphate Tanks | D9: Tank size L 5′ × W 5′ × H 5′, HR sheet 3 mm × 5 pcs. Side platform 1½″ × 1½″ pipe + ⅜″ square rod. Over-head conveyor 1 ton with control panel. Over-head conveyor structure. Overflow trays. Heat chamber 5″ pipe + burner ¾ HP × 2 pcs. Control panel. Paint. | E9: 2185000 | F9: 1 | G9: =E9*F9 -> 2185000 | H9: Welded with MIG welding; fewer joints than others
B10: 4 | C10: Baking Oven + Dry Oven (1 + 1) | D10: Baking oven L 14′ × W 10′ × H 8′ with inner 1 mm galvanized sheet. Air circulation blower 3 HP motor. Burner 1 HP for ovens. Insulated with glasswool jacketed sandwich, extendable, bolted. Heat exchanger + heat chamber. Control panel. | E10: 1898000 | F10: 1 | G10: =E10*F10 -> 1898000 | H10: Totally adjustable and bolted
B11: 5 | C11: 2-Wheel Vehicle Test Bench (with Control Panel) | D11: Speed test 8″ roller × 2. Brake test 4.5″ roller × 2. 3″ × 1½″ channel + 1½″ angle structure, base sheet 3 mm. Alignment test, light-lux test. PLC-based 24″ LED display control system. Real-time database + print report. | E11: 1650000 | F11: 1 | G11: =E11*F11 -> 1650000
B12: 6 | C12: Hub Motor Test System | D12: Speed (RPM), voltage, current, torque, efficiency, load test. Auto + manual operate system. PLC-based HMI touch screen, graphical interface, trending, and test report. | E12: 950000 | F12: 1 | G12: =E12*F12 -> 950000
B13: SUBTOTAL | G13: =SUM(G7:G12) -> 11278000
B14: Sales Tax (quote is exclusive of all taxes — edit rate cell below) | G14: =G13*0 -> 0 | H14: Tax rate placeholder = 0%; edit if applicable
B15: GRAND TOTAL (PKR) | G15: =G13+G14 -> 11278000 | H15: As per quote: PKR 11,278,000 (zero tax)
B17: TERMS & CONDITIONS (per vendor quote, page 2)
B18: Quotation validity | D18: 3 days from date of issue (5 May 2026) — material-price volatility
B19: Payment terms | D19: As per mutual understanding
B20: Pricing | D20: Exclusive of all applicable taxes
B21: Warranty | D21: 1 year service warranty · all parts available on demand
B22: Delivery & install | D22: Within 90 working days from confirmed PO + advance payment (subject to site readiness)
B23: Excluded scope | D23: Civil works · electrical power works · cables & DBs · logistics/transport · power supply · gate pass · approvals · light & fan power wires
B24: Other | D24: All other parameters executed strictly per client specifications

Sheet 9. CapEx Additional
B2: CapEx — Additional Items (not in AIT quote)
B3: ★ EDIT THE YELLOW CELLS — these are indicative ROM estimates only. Replace with actual quotes.
B5: # | C5: Item / Scope | D5: Indicative Cost (PKR) | E5: Confidence | F5: Notes
B6: 1 | C6: Welding equipment (MIG × 2 + helmets, fixtures, tools) | D6: 600000 | E6: Med | F6: Beyond what AIT supplies for assembly line — for weld shop
B7: 2 | C7: Sub-assembly workbenches (11 stations) | D7: 275000 | E7: High | F7: ~PKR 25k per bench × 11
B8: 3 | C8: Sub-assembly tools, fixtures, torque wrenches | D8: 500000 | E8: Med | F8: Pneumatic & manual; calibration kits
B9: 4 | C9: Battery-box (SA-10) safety fit-out | D9: 300000 | E9: Med | F9: ★ Insulated mats, fire blanket, gas detector, dedicated extinguisher
B10: 5 | C10: Material handling — pallet trucks, trolleys, hand-jacks | D10: 300000 | E10: High | F10: 2 pallet trucks + 6 trolleys
B11: 6 | C11: Storage racks (Incoming + Finished Goods) | D11: 600000 | E11: Med | F11: Heavy-duty pallet racking + bin shelving
B12: 7 | C12: Frame tagging — VIN punch + label printer + scanner | D12: 200000 | E12: High
B13: 8 | C13: Quality inspection tools (gauges, multimeters, etc.) | D13: 350000 | E13: Med | F13: IQC + in-process + final
B14: 9 | C14: Compressed air system (compressor + piping + dryer) | D14: 600000 | E14: Med | F14: For paint, pneumatic tools, blow-off
B15: 10 | C15: IT setup (PCs, printers, LAN, basic ERP / MRP) | D15: 1200000 | E15: Med | F15: 10 desktops + 2 printers + network + entry-level ERP licence
B16: 11 | C16: Office furniture (desks, chairs, meeting room) | D16: 400000 | E16: High
B17: 12 | C17: Lockers, canteen kit, washrooms fit-out | D17: 500000 | E17: Med | F17: Worker amenities
B18: 13 | C18: Safety equipment (PPE, fire extinguishers, eye-wash) | D18: 250000 | E18: High | F18: Initial stock
B19: 14 | C19: Misc. fit-out, signage, line marking, contingency | D19: 500000 | E19: Low | F19: 10% contingency on the above
B20: SUBTOTAL — additional CapEx | D20: =SUM(D6:D19) -> 6575000

Sheet 10. CapEx Summary
B2: CapEx Summary — All-In Project Cost
B3: Roll-up of all capital costs to set up the plant
B5: # | C5: Category | D5: Amount (PKR) | E5: % of Total | F5: Notes
B6: 1 | C6: Quoted equipment (AIT) | D6: ='8. CapEx Quoted'!G15 -> 11278000 | E6: =D6/$D$14 -> 0.47281264 | F6: Quote F18-1109B-176
B7: 2 | C7: Additional equipment | D7: ='9. CapEx Additional'!D20 -> 6575000 | E7: =D7/$D$14 -> 0.27564667 | F7: Items beyond AIT scope
B8: Equipment subtotal | D8: =SUM(D6:D7) -> 17853000 | E8: =D8/$D$14 -> 0.74845931
B9: 3 | C9: Civil works (site prep, flooring, partitions, paint, plumbing) | D9: 5000000 | E9: =D9/$D$14 -> 0.20961724 | F9: TBD — obtain civil contractor quote
B10: 4 | C10: Electrical works (power supply, DBs, cabling, lights, fans) | D10: 1000000 | E10: =D10/$D$14 -> 0.041923448 | F10: TBD — required per AIT quote exclusions
B11: 5 | C11: Land / building (lease deposit or purchase) | D11: 0 | E11: =D11/$D$14 -> 0 | F11: TBD — own or rent decision
B12: 6 | C12: Working capital (initial inventory, 1-month opex) | D12: 0 | E12: =D12/$D$14 -> 0 | F12: TBD — depends on credit terms
B13: 7 | C13: Other (regulatory, training, launch contingency) | D13: 0 | E13: =D13/$D$14 -> 0 | F13: TBD
B14: PROJECT CapEx TOTAL | D14: =D8+SUM(D9:D13) -> 23853000 | E14: 1

Sheet 11. Assumptions & Notes
B2: Assumptions, Open Items & Things to Verify
B4: PRODUCTION ASSUMPTIONS
B5: Annual production target | C5: 5,000 e-bikes per year
B6: Working calendar | C6: 250 days/year, 1 shift/day, 480 min/shift (8 hrs)
B7: Daily production rate | C7: 20 bikes per day
B8: Takt time | C8: 24 minutes per bike
B9: Yield assumption | C9: 100% first-pass (to be refined with actual data)
B10: Shift expansion plan | C10: Single shift in Y1 — scale to 2 shifts for ~10,000 bikes/yr if needed
B12: FACILITY ASSUMPTIONS
B13: Building footprint | C13: 150 ft × 80 ft = 12,000 sq ft single-story | D13: needs to be addressed to realistic
B14: Functional area | C14: ~4,880 sq ft (40.7%) — production zones
B15: Aisles & clearance | C15: ~7,120 sq ft (59.3%) — forklift lanes, fire egress, 4 ft clearance around main line
B16: Main aisle width | C16: Minimum 8 ft for forklift; 4 ft for sub-assy walkways
B17: Ceiling height | C17: Minimum 20 ft for overhead conveyor (per AIT phosphate-tank scope)
B18: Power supply | C18: NOT included in AIT quote — client scope; estimate 200–300 kVA load
B19: Compressed air | C19: Required for paint + pneumatic tools — included in additional CapEx
B21: LABOUR ASSUMPTIONS — EDIT THE YELLOW CELLS ON SHEET 7
B22: Salary rates | C22: Indicative Pakistani manufacturing rates, mid-2026. REPLACE with your actuals on Sheet 7.
B23: Bonus / overtime | C23: NOT included in monthly rate — add separately if applicable
B24: Benefits (EOBI, SS, Eid) | C24: NOT included — typically adds 8–12% on top of base salary
B25: Annual leave / sick days | C25: Not modelled in current version
B26: MA-04 (Skilled) | C26: Sub-assembly convergence point — needs experienced fitter
B27: MA-06 (Senior) | C27: Doubles as final OQC sign-off
B28: SA-10 (Battery Box) ★ | C28: Safety-critical — ALWAYS 2 skilled workers, never under-staff
B30: QUOTE ASSUMPTIONS (AIT — F18-1109B-176)
B31: Quote validity | C31: Only 3 days from 5 May 2026 — material-price volatility. CONFIRM/RENEGOTIATE.
B32: Tax treatment | C32: Quote is exclusive of all taxes. Tax row on Sheet 8 is set to 0% — edit if needed.
B33: Delivery timeline | C33: 90 working days from confirmed PO + advance payment
B34: Vendor warranty | C34: 1 year service + parts available on demand
B35: Excluded scope | C35: Civil, electrical, cables, DBs, logistics, transport, lighting, fans — all client scope
B36: Site readiness | C36: Vendor delivery timeline assumes site is ready — schedule civil/elec works first
B38: OPEN ITEMS / TO BE COSTED
B39: Civil works | C39: Site prep, flooring, partitions, plumbing, painting — get civil contractor quotes
B40: Electrical works | C40: Power supply, DBs, cables, lights, fans, earthing — get electrical contractor quotes
B41: Land / building | C41: Lease deposit or purchase cost — depends on location (Lahore/Karachi/Islamabad)
B42: Working capital | C42: Initial inventory + 1-month operating cost float
B43: Annual operating cost (opex) | C43: Utilities, consumables, R&M — to be modelled in next iteration
B44: Depreciation & ROI | C44: To be modelled in next iteration with full 5-year cashflow
B45: Vendor approvals / regulatory | C45: PEC registration, EPA NOC, fire safety — client scope
B46: Insurance | C46: Plant, machinery, inventory, workmen's compensation
...
